Workbook

Sheet Summary
A1: Mohammed Mohsen Mohammed Al-Sakkaf (A23CS4026) - SCSEH01 Bachelor in Software Engineering with Honours, UTM - intake 2024/2025
A2: Study plan v2 - as of 2026-10-14. Evidence tags: P = proven in a document, C = calculated, A = assumption. Category totals below are live formulas over sheet 'Plan'.
A4: Category | B4: Meaning | C4: Required | D4: Earned | E4: Registered (slip) | F4: To add (SEM 5, unconfirmed) | G4: Planned SEM 6-9 | H4: Remaining after plan | I4: Still needed today (Req - Earned)
A5: T | B5: Faculty core (Wajib/Teras Fakulti) | C5: 82 | D5: =SUMIFS(Plan!$F:$F,Plan!$G:$G,"T",Plan!$J:$J,"Earned") | E5: =SUMIFS(Plan!$F:$F,Plan!$G:$G,"T",Plan!$J:$J,"Registered") | F5: =SUMIFS(Plan!$F:$F,Plan!$G:$G,"T",Plan!$J:$J,"To add") | G5: =SUMIFS(Plan!$F:$F,Plan!$G:$G,"T",Plan!$J:$J,"Planned") | H5: =C5-D5-E5-F5-G5 | I5: =C5-D5
A6: E | B6: Programme electives (Elektif) | C6: 18 | D6: =SUMIFS(Plan!$F:$F,Plan!$G:$G,"E",Plan!$J:$J,"Earned") | E6: =SUMIFS(Plan!$F:$F,Plan!$G:$G,"E",Plan!$J:$J,"Registered") | F6: =SUMIFS(Plan!$F:$F,Plan!$G:$G,"E",Plan!$J:$J,"To add") | G6: =SUMIFS(Plan!$F:$F,Plan!$G:$G,"E",Plan!$J:$J,"Planned") | H6: =C6-D6-E6-F6-G6 | I6: =C6-D6
A7: U | B7: University (Umum Universiti) incl. 4 Free Electives = 12 | C7: 20 | D7: =SUMIFS(Plan!$F:$F,Plan!$G:$G,"U",Plan!$J:$J,"Earned") | E7: =SUMIFS(Plan!$F:$F,Plan!$G:$G,"U",Plan!$J:$J,"Registered") | F7: =SUMIFS(Plan!$F:$F,Plan!$G:$G,"U",Plan!$J:$J,"To add") | G7: =SUMIFS(Plan!$F:$F,Plan!$G:$G,"U",Plan!$J:$J,"Planned") | H7: =C7-D7-E7-F7-G7 | I7: =C7-D7
A8: B | B8: English / languages (Bahasa Inggeris) | C8: 6 | D8: =SUMIFS(Plan!$F:$F,Plan!$G:$G,"B",Plan!$J:$J,"Earned") | E8: =SUMIFS(Plan!$F:$F,Plan!$G:$G,"B",Plan!$J:$J,"Registered") | F8: =SUMIFS(Plan!$F:$F,Plan!$G:$G,"B",Plan!$J:$J,"To add") | G8: =SUMIFS(Plan!$F:$F,Plan!$G:$G,"B",Plan!$J:$J,"Planned") | H8: =C8-D8-E8-F8-G8 | I8: =C8-D8
A9: K | B9: Co-curriculum (Kokurikulum) | C9: 2 | D9: =SUMIFS(Plan!$F:$F,Plan!$G:$G,"K",Plan!$J:$J,"Earned") | E9: =SUMIFS(Plan!$F:$F,Plan!$G:$G,"K",Plan!$J:$J,"Registered") | F9: =SUMIFS(Plan!$F:$F,Plan!$G:$G,"K",Plan!$J:$J,"To add") | G9: =SUMIFS(Plan!$F:$F,Plan!$G:$G,"K",Plan!$J:$J,"Planned") | H9: =C9-D9-E9-F9-G9 | I9: =C9-D9
A10: TOTAL | C10: =SUM(C5:C9) | D10: =SUM(D5:D9) | E10: =SUM(E5:E9) | F10: =SUM(F5:F9) | G10: =SUM(G5:G9) | H10: =SUM(H5:H9) | I10: =SUM(I5:I9)
A11: UHLB1112 English Communication Skills (2, HL/HW) is NOT in these totals: the audit counts it under B and in KD 57 -> conflict K1. Audit 'Jumlah kredit dapat' (incl. registered + UHLB1112): T49 E9 U7 B2 K2 = 69.
A13: KD projection (if every course is passed)
A14: Point | B14: Official KD (incl. UHLB1112) | C14: Credits toward 128 | D14: Tag | E14: Gate check
A15: Now - after 2025/26-II (official) | B15: 57 | C15: 55 | D15: P [RES] | E15: -
A16: End SEM 5 - registered 12 only | B16: 69 | C16: 67 | D16: C | E16: < 80: SCSE3242 not possible in SEM 6
A17: End SEM 5 - registered 12 + to add 6 | B17: 75 | C17: 73 | D17: C (A3) | E17: < 80: SCSE3242 still not possible in SEM 6
A18: End SEM 6 (+17) | B18: 92 | C18: 90 | D18: C (A4) | E18: >= 80: SCSE3242 OK in SEM 7; 92 IT gate reached (official KD)
A19: End SEM 7 (+13) | B19: 105 | C19: 103 | D19: C
A20: End SEM 8 (+13) | B20: 118 | C20: 116 | D20: C | E20: >= 92 + CGPA >= 2.0: Industrial Training OK in SEM 9
A21: End SEM 9 (+12) | B21: 130 | C21: 128 | D21: C | E21: 128 graduation credits reached (official KD 130 incl. UHLB1112, see K1)
A23: CGPA
A24: Current JMN (P) | B24: 155.66
A25: Current KK (P) | B25: 61
A26: Current CGPA = JMN/KK (C) | B26: =ROUND(B24/B25,4)
A27: Graded credits h this semester (edit) | B27: 18
A28: Average grade point this semester (edit; 4 = all A) | B28: 4
A29: Projected CGPA = (JMN + gp*h)/(KK + h) (C) | B29: =ROUND((B24+B28*B27)/(B25+B27),4)
A30: Ceiling, 12 registered credits all A (C) | B30: =ROUND((B24+4*12)/(B25+12),4)
A31: Ceiling, 18 credits (12 + 6 to add) all A (C, A3) | B31: =ROUND((B24+4*18)/(B25+18),4)
A32: Repeat effect example (A5): replace both D (3 cr x 1.00) with B (3.00), from today's base | B32: =ROUND((B24-6+18)/B25,4)
A33: Repeat replacement is an assumption (A5). It is supported by JMN/KK matching exactly when the first D attempts of SCSR2213 and SCST1223 are left out. SFMX1063 (NFE) and the UHLB/UHLF adds are assumed to be graded.

Sheet Plan
A1: Semester | B1: Code | C1: Course (English name) | D1: Credits | E1: Status | F1: Counts toward 128 | G1: Category (T/E/U/B/K; U-FE = free-elective slot inside U) | H1: Grade / section | I1: Prerequisite | J1: Bucket | K1: Prerequisite met? | L1: Evidence (P/C/A) | M1: Source | N1: Note
A2: Y1 S1 - 2024/2025 Sem I (202420251) - completed | B2: SCSE1013 | C2: Fundamental Programming Concepts | D2: 3 | E2: Passed (C) | F2: 3 | G2: T | H2: C | I2: - | J2: Earned | K2: - | L2: P | M2: AUD
A3: Y1 S1 - 2024/2025 Sem I (202420251) - completed | B3: SCST1123 | C3: Mathematics for Software Engineer | D3: 3 | E3: Passed (D+) | F3: 3 | G3: T | H3: D+ | I3: - | J3: Earned | K3: - | L3: P | M3: AUD
A4: Y1 S1 - 2024/2025 Sem I (202420251) - completed | B4: SCSR1013 | C4: Digital Logic | D4: 3 | E4: Passed (C+) | F4: 3 | G4: T | H4: C+ | I4: - | J4: Earned | K4: - | L4: P | M4: AUD
A5: Y1 S1 - 2024/2025 Sem I (202420251) - completed | B5: SCST1143 | C5: Database Engineering | D5: 3 | E5: Passed (C+) | F5: 3 | G5: T | H5: C+ | I5: - | J5: Earned | K5: - | L5: P | M5: AUD
A6: Y1 S1 - 2024/2025 Sem I (202420251) - completed | B6: ULRS1032 | C6: Integrity and Anti-Corruption Course | D6: 2 | E6: Passed (A+) | F6: 2 | G6: U | H6: A+ | I6: - | J6: Earned | K6: - | L6: P | M6: AUD
A7: Y1 S1 - 2024/2025 Sem I (202420251) - completed | B7: UHLB1112 | C7: English Communication Skills | D7: 2 | E7: Passed (HL (status HW)) | F7: 0 | G7: B* (outside 128) | H7: HL (status HW) | I7: - | J7: - | K7: - | L7: P | M7: AUD/STR | N7: Audit lists it under B and it is inside KD 57; [STR] makes it an extra course for low English scores. Kept OUTSIDE the 128 here (conflict K1)
A8: Y1 S1 - 2024/2025 Sem I (202420251) - completed | B8: FE I | C8: Free Elective I (slot) - never taken | D8: 3 | E8: Elective slot TBD | F8: 0 | G8: U | H8: - | I8: - | J8: - | K8: - | L8: P (gap) / A (moved) | M8: STR/AUD | N8: Category label: U-FE. Not in audit. Moved to SEM 7
A9: Y1 S2 - 2024/2025 Sem II (202420252) - completed | B9: SCSE1203 | C9: Software Engineering Principles | D9: 3 | E9: Passed (B) | F9: 3 | G9: T | H9: B | I9: SCSE1013 | J9: Earned | K9: Yes (C) | L9: P | M9: AUD/STR
A10: Y1 S2 - 2024/2025 Sem II (202420252) - completed | B10: SCSE1224 | C10: Advanced Programming | D10: 4 | E10: Passed (C+) | F10: 4 | G10: T | H10: C+ | I10: SCSE1013 | J10: Earned | K10: Yes (C) | L10: P | M10: AUD/STR
A11: Y1 S2 - 2024/2025 Sem II (202420252) - completed | B11: SCSR1033 | C11: Computer Organization and Architecture | D11: 3 | E11: Passed (C+) | F11: 3 | G11: T | H11: C+ | I11: SCSR1013 | J11: Earned | K11: Yes (C+) | L11: P | M11: AUD/STR
A12: Y1 S2 - 2024/2025 Sem II (202420252) - completed | B12: SCSR2213 | C12: Network Communications (1st attempt) | D12: 3 | E12: Failed - superseded by repeat | F12: 0 | G12: T | H12: D (G) | I12: - | J12: - | K12: - | L12: P | M12: AUD | N12: Repeated 2025/26-II -> B-
A13: Y1 S2 - 2024/2025 Sem II (202420252) - completed | B13: SCST1223 | C13: Probability and Statistical Data Analysis (1st attempt) | D13: 3 | E13: Failed - superseded by repeat | F13: 0 | G13: T | H13: D (G) | I13: - | J13: - | K13: - | L13: P | M13: AUD | N13: Repeated 2025/26-II -> C-
A14: Y1 S2 - 2024/2025 Sem II (202420252) - completed | B14: UHLM1012 | C14: Malay Language for Communication 2 | D14: 2 | E14: Passed (A-) | F14: 2 | G14: U | H14: A- | I14: - | J14: Earned | K14: - | L14: P | M14: AUD | N14: International-student version of ULRS1182
A15: Y2 S1 - 2025/2026 Sem I (202520261) - completed | B15: SCSE2103 | C15: Data Structure and Algorithm | D15: 3 | E15: Passed (B) | F15: 3 | G15: T | H15: B | I15: SCSE1013 | J15: Earned | K15: Yes | L15: P | M15: AUD/STR
A16: Y2 S1 - 2025/2026 Sem I (202520261) - completed | B16: SCSE2123 | C16: Software Requirements Engineering | D16: 3 | E16: Passed (C+) | F16: 3 | G16: T | H16: C+ | I16: SCSE1203 | J16: Earned | K16: Yes | L16: P | M16: AUD/STR
A17: Y2 S1 - 2025/2026 Sem I (202520261) - completed | B17: SCSE2133 | C17: Software Process and Project Management | D17: 3 | E17: Passed (B-) | F17: 3 | G17: T | H17: B- | I17: SCSE1203 | J17: Earned | K17: Yes | L17: P | M17: AUD/STR
A18: Y2 S1 - 2025/2026 Sem I (202520261) - completed | B18: SCSM2113 | C18: Human Computer Interaction Fundamentals | D18: 3 | E18: Passed (B-) | F18: 3 | G18: T | H18: B- | I18: SCSE1203 | J18: Earned | K18: Yes | L18: P | M18: AUD/STR
A19: Y2 S1 - 2025/2026 Sem I (202520261) - completed | B19: SCSR2043 | C19: Operating Systems | D19: 3 | E19: Passed (A-) | F19: 3 | G19: T | H19: A- | I19: - | J19: Earned | K19: - | L19: P | M19: AUD
A20: Y2 S1 - 2025/2026 Sem I (202520261) - completed | B20: ULRF2622 | C20: Football (Service Learning & Community Engagement slot ULRF2xx2) | D20: 2 | E20: Passed (A) | F20: 2 | G20: K | H20: A | I20: - | J20: Earned | K20: - | L20: P | M20: AUD/STR
A21: Y2 S2 - 2025/2026 Sem II (202520262) - completed (GPA 2.22, CGPA 2.55) | B21: SCSE2243 | C21: Application Development Project I | D21: 3 | E21: Passed (A) | F21: 3 | G21: T | H21: A | I21: SCSE1203, SCSE2123 | J21: Earned | K21: Yes | L21: P | M21: RES/AUD
A22: Y2 S2 - 2025/2026 Sem II (202520262) - completed (GPA 2.22, CGPA 2.55) | B22: SCSM2223 | C22: Cross-Platform Application Development | D22: 3 | E22: Passed (B) | F22: 3 | G22: T | H22: B | I22: SCST1143 | J22: Earned | K22: Yes | L22: P | M22: RES/AUD
A23: Y2 S2 - 2025/2026 Sem II (202520262) - completed (GPA 2.22, CGPA 2.55) | B23: SCSR2213 | C23: Network Communications (repeat, UK) | D23: 3 | E23: Passed (B-) | F23: 3 | G23: T | H23: B- | I23: - | J23: Earned | K23: - | L23: P | M23: RES/AUD
A24: Y2 S2 - 2025/2026 Sem II (202520262) - completed (GPA 2.22, CGPA 2.55) | B24: SCST1223 | C24: Probability and Statistical Data Analysis (repeat, UK) | D24: 3 | E24: Passed (C-) | F24: 3 | G24: T | H24: C- | I24: - | J24: Earned | K24: - | L24: P | M24: RES/AUD
A25: Y2 S2 - 2025/2026 Sem II (202520262) - completed (GPA 2.22, CGPA 2.55) | B25: SCSE2233 | C25: Software Design and Architecture | D25: 3 | E25: Repeat needed | F25: 0 | G25: T | H25: D (G, UM) | I25: SCSE1203 | J25: - | K25: Yes | L25: P | M25: RES/AUD | N25: Not earned. Repeat planned in SEM 6
A26: Y2 S2 - 2025/2026 Sem II (202520262) - completed (GPA 2.22, CGPA 2.55) | B26: SCSP3213 | C26: Business Intelligence (Y2S2 programme elective) | D26: 3 | E26: Repeat needed | F26: 0 | G26: E | H26: D (G, UM) | I26: - | J26: - | K26: - | L26: P | M26: RES/AUD | N26: Not earned. Repeat planned in SEM 6
A27: Y2 S2 - 2025/2026 Sem II (202520262) - completed (GPA 2.22, CGPA 2.55) | B27: UHLB2122 | C27: Professional Communication Skills 1 (Y2S2 in [STR]) | D27: 2 | E27: Not yet taken | F27: 0 | G27: B | H27: - | I27: - | J27: - | K27: - | L27: P | M27: STR | N27: Moved to SEM 5 as 'to add'
A28: Y2 S2 - 2025/2026 Sem II (202520262) - completed (GPA 2.22, CGPA 2.55) | B28: ULRS1022 | C28: Philosophy and Current Issues (Y2S2 in [STR]) | D28: 2 | E28: Not yet taken | F28: 0 | G28: U | H28: - | I28: - | J28: - | K28: - | L28: P | M28: STR/AUD | N28: Not in audit. Moved to SEM 7
A29: SEM 5 - Y3 S1 - 2026/2027 Sem I (202620271) - CURRENT: 12 Oct 2026 - 21 Mar 2027 | B29: SCSE3103 | C29: Cognitive Computing | D29: 3 | E29: Registered (slip) | F29: 3 | G29: E | H29: sec 05 | I29: - | J29: Registered | K29: - | L29: P | M29: SLIP/AUD
A30: SEM 5 - Y3 S1 - 2026/2027 Sem I (202620271) - CURRENT: 12 Oct 2026 - 21 Mar 2027 | B30: SCSE3143 | C30: Ubiquitous Computing | D30: 3 | E30: Registered (slip) | F30: 3 | G30: E | H30: sec 05 | I30: - | J30: Registered | K30: - | L30: P | M30: SLIP/AUD
A31: SEM 5 - Y3 S1 - 2026/2027 Sem I (202620271) - CURRENT: 12 Oct 2026 - 21 Mar 2027 | B31: SCSE3203 | C31: Special Topics | D31: 3 | E31: Registered (slip) | F31: 3 | G31: E | H31: sec 15 | I31: - | J31: Registered | K31: - | L31: P | M31: SLIP/AUD | N31: Time/room still unknown
A32: SEM 5 - Y3 S1 - 2026/2027 Sem I (202620271) - CURRENT: 12 Oct 2026 - 21 Mar 2027 | B32: SFMX1063 | C32: Information Technology in Business (fills Free Elective II slot) | D32: 3 | E32: Registered (slip) | F32: 3 | G32: U | H32: sec 02, FC, NFE | I32: - | J32: Registered | K32: - | L32: P | M32: SLIP/AUD | N32: Category label: U-FE. Audit lists it under U (Umum Universiti). It IS the FE II slot - no extra FE II row
A33: SEM 5 - Y3 S1 - 2026/2027 Sem I (202620271) - CURRENT: 12 Oct 2026 - 21 Mar 2027 | B33: UHLB2122 | C33: Professional Communication Skills 1 | D33: 2 | E33: To add (planned, unconfirmed) | F33: 2 | G33: B | H33: add 15 Oct | I33: - | J33: To add | K33: - | L33: A | M33: MOH/OLD | N33: Not on slip of 04 Oct; date not in official sources
A34: SEM 5 - Y3 S1 - 2026/2027 Sem I (202620271) - CURRENT: 12 Oct 2026 - 21 Mar 2027 | B34: UHLB3132 | C34: Professional Communication Skills (2) | D34: 2 | E34: To add (planned, unconfirmed) | F34: 2 | G34: B | H34: add 15 Oct | I34: none listed in [STR] | J34: To add | K34: Yes (none listed) | L34: A | M34: MOH/OLD/STR | N34: Not on slip; check if UHLB2122 must come first
A35: SEM 5 - Y3 S1 - 2026/2027 Sem I (202620271) - CURRENT: 12 Oct 2026 - 21 Mar 2027 | B35: UHLF1112 | C35: French Language (French 1) - foreign language elective | D35: 2 | E35: To add (planned, unconfirmed) | F35: 2 | G35: B | H35: sec 13 Wed 9-11am | I35: - | J35: To add | K35: - | L35: A (status) / P (section) | M35: FL/MOH | N35: Late reg. by 14 Oct (not in official sources). See K1 before adding
A36: SEM 6 - Y3 S2 - 2026/2027 Sem II: 22 Mar - 3 Oct 2027 (lectures 22 Mar - 4 Jul, exams 12-25 Jul) | B36: SCSE2233 | C36: Software Design and Architecture - REPEAT | D36: 3 | E36: Repeat needed | F36: 3 | G36: T | H36: was D | I36: SCSE1203 | J36: Planned | K36: Yes (B) | L36: P (prereq) / A (offered Sem II: [STR] Y2S2) | M36: STR/AUD | N36: Unblocks SCSE3213
A37: SEM 6 - Y3 S2 - 2026/2027 Sem II: 22 Mar - 3 Oct 2027 (lectures 22 Mar - 4 Jul, exams 12-25 Jul) | B37: SCSP3213 | C37: Business Intelligence - REPEAT | D37: 3 | E37: Repeat needed | F37: 3 | G37: E | H37: was D | I37: - | J37: Planned | K37: - | L37: A (offered Sem II: [STR] Y2S2) | M37: STR/AUD | N37: Alternative for the Y2S2 elective: SCSB2103 Bioinformatics I or SCSP2753 Data Mining (would not replace the D - A)
A38: SEM 6 - Y3 S2 - 2026/2027 Sem II: 22 Mar - 3 Oct 2027 (lectures 22 Mar - 4 Jul, exams 12-25 Jul) | B38: SCSR3133 | C38: Secure Software Programming | D38: 3 | E38: Not yet taken | F38: 3 | G38: T | H38: - | I38: 'SCSM 2213' per [STR] | J38: Planned | K38: Likely (A): code not in [CUR]; SCSM2113 B-/SCSM2223 B passed | L38: A | M38: STR/CUR | N38: Conflict K3
A39: SEM 6 - Y3 S2 - 2026/2027 Sem II: 22 Mar - 3 Oct 2027 (lectures 22 Mar - 4 Jul, exams 12-25 Jul) | B39: SCSE3223 | C39: Application Development Project II | D39: 3 | E39: Not yet taken | F39: 3 | G39: T | H39: - | I39: SCSE2243 | J39: Planned | K39: Yes (A) | L39: P (prereq) / A (sem) | M39: STR/RES
A40: SEM 6 - Y3 S2 - 2026/2027 Sem II: 22 Mar - 3 Oct 2027 (lectures 22 Mar - 4 Jul, exams 12-25 Jul) | B40: SCSE3233 | C40: Professional Practice in Software Engineering | D40: 3 | E40: Not yet taken | F40: 3 | G40: T | H40: - | I40: SCSE1203 | J40: Planned | K40: Yes (B) | L40: P (prereq) / A (sem) | M40: STR/AUD
...

Sheet Semester loads
A1: Semester | B1: Credits (registered/to add/planned) | C1: Official KD after (if all passed)
A2: SEM 5 - Y3 S1 - 2026/2027 Sem I (202620271) - CURRENT: 12 Oct 2026 - 21 Mar 2027 | B2: 18 | C2: 69 (registered only) / 75 (with adds)
A3: SEM 6 - Y3 S2 - 2026/2027 Sem II: 22 Mar - 3 Oct 2027 (lectures 22 Mar - 4 Jul, exams 12-25 Jul) | B3: 17 | C3: 92
A4: SEM 7 - Y4 S1 - 2027/2028 Sem I (approx. Oct 2027 - Mar 2028; dates A) | B4: 13 | C4: 105
A5: SEM 8 - Y4 S2 - 2027/2028 Sem II (approx. Mar - Jul 2028; dates A) | B5: 13 | C5: 118
A6: SEM 9 - 2028/2029 Sem I (approx. Oct 2028 - Feb 2029; dates A) - Industrial Training | B6: 12 | C6: 130

Sheet Changes vs old plan
A1: # | B1: What changed
A2: 1 | B2: SEM 5 load: old block said 19 (counted a blank 'Free Elective II' on top of SFMX1063, while UHLB2122 sat in the Y2S2 block). Now: 12 registered + 6 to add (UHLB2122, UHLB3132, UHLF1112) = 18.
A3: 2 | B3: SFMX1063 Information Technology in Business = category U (audit), filling the FE II slot. No second FE II. FE I (never taken in Y1S1) is now an explicit open slot, placed in SEM 7.
A4: 3 | B4: Repeats SCSE2233 Software Design and Architecture and SCSP3213 Business Intelligence: old plan had no future slot. Now in SEM 6 (Sem II, the semester where [STR] offers them).
A5: 4 | B5: ULRS1022 Philosophy and Current Issues (never taken) now placed in SEM 7.
A6: 5 | B6: SCSE3242 Software Engineering Project I moved from SEM 6 to SEM 7: KD can reach at most 75 by the start of SEM 6 (<80), and 92 by SEM 7.
A7: 6 | B7: SCSE3213 Software Quality and Testing moved from SEM 6 to SEM 8 (needs SCSE2233 passed first). SCSE4214 Software Engineering Project II stays in SEM 8. Industrial Training SCSE4108/SCSE4114 moves to SEM 9.
A8: 7 | B8: 'SCSRxxx3 Program Elective' x2 replaced by the official Y4S2 options: SCSR4453, SCSR4973, SECB3133, SECB3203, PRISMS.
A9: 8 | B9: UHLB1112 English Communication Skills no longer inside a semester total (old Y1S1 = 19). [STR] Y1S1 = 17; UHLB1112 is shown separately (conflict K1).
A10: 9 | B10: Every row now has a text status, category, prerequisite check, source and evidence tag (P/C/A). Added category totals, KD projection and CGPA section.

Sheet Assumptions
A1: ID | B1: Assumption
A2: A1 | B2: Offering semester = where [STR] places the course (Year x Sem 1 = Sem I in Oct, Sem 2 = Sem II in Mar). [STR] does not state offerings.
A3: A2 | B3: SCSE3242 Software Engineering Project I is offered in Sem I (SEM 7). Fallback F1: if it runs only in Sem II, swap: SEM 7 = Industrial Training SCSE4108 + SCSE4114, SEM 8 = SCSE3242 + SCSE3213 + ULRS1022 + FE I/III/IV, and SCSE4214 + 2 programme electives in SEM 9 (if offered in Sem I) or SEM 10 (Mar-Jul 2029). SEM 10 matches the 29 Aug 2029 expected graduation.
A4: A3 | B4: The three SEM 5 adds (UHLB2122, UHLB3132, UHLF1112) get registered. If not, KD after SEM 5 = 69 (not 75), after SEM 6 = 86: still >= 80 for SCSE3242 in SEM 7. The 6 B credits then need a later semester (offerings of UHLB/UHLx in other semesters not in sources).
A5: A4 | B5: Every course from now on is passed at the first try. Each failure removes its credits from all later KD figures.
A6: A5 | B6: A repeat replaces the old D in the CGPA (UM/UK). Calculated support: JMN 155.66 / KK 61 come out exactly when the first D attempts of SCSR2213 and SCST1223 are left out. The official rule is not in the sources.
A7: A6 | B7: The '80 credits' (SCSE3242) and '92 credits' (Industrial Training) gates are measured as official KD (which includes UHLB1112). On the 128-basis the numbers are 2 lower (90 after SEM 6), but the gates still hold where they are used.
A8: A7 | B8: Dates for 2027/2028 and 2028/2029 are estimated from the 2026/2027 pattern. Only the 2026/2027 calendar is in the sources.
A9: A8 | B9: Which slot SFMX1063 fills (FE II) is a labelling choice. The audit only lists it under U (Umum Universiti); the credit effect is the same.
A10: A9 | B10: Loads of 12-18 credits are allowed. The maximum credit load rule is not in the sources.

Sheet Conflicts
A1: ID | B1: Conflict / open question
A2: K1 | B2: UHLB1112 English Communication Skills: the audit lists it under B (Bahasa Inggeris, 6) and counts its 2 credits in KD 57 (49 T + 4 U + 2 K + 2 = 57). [STR] treats it as an extra course for students with low English scores. This plan keeps B6 = UHLB2122 + UHLB3132 + UHLF1112 (plan total 128; official KD would end at 130). ASK THE ADVISOR TODAY: if UHLB1112 counts toward B6, only 4 more B credits are needed and one of the three adds (e.g. UHLF1112) may be unnecessary.
A3: K2 | B3: [CUR] lists UKQA2022 Digital Media & Community (2) under FACULTY CORE, which makes 84 against the 82 heading. [STR] and the audit do not list it, so it is excluded here. Advisor to confirm.
A4: K3 | B4: SCSR3133 Secure Software Programming prerequisite 'SCSM 2213' ([STR]) is not a course in [CUR]. It is probably SCSM2113 or SCSM2223, both passed.
A5: K4 | B5: Graduation timing: [STR] = 8 semesters (Jul 2028). This plan ends after SEM 9 (approx. Feb 2029). Status letter (via Omar) says expected graduation 29 Aug 2029; fallback F1 also fits that date.
A6: K5 | B6: PRISMS codes differ: [STR] SECR/SECP/SECJ5xx3 vs [CUR] SCSR/SCSP/SCSJ5xxx. PRISMS eligibility (likely CGPA-based) is not in the sources; at CGPA 2.55 it may not be open.
A7: K6 | B7: [STR] names the foreign-language slot 'UHLx1122'; [CUR] and [FL] list UHLF1112 French Language under ENGLISH 6.
A8: K7 | B8: [CUR] UNIVERSITY list includes SCSE4213 / SCSE4223 (Computing courses), but the [STR] footnote says free electives must come from other faculties. Pick FE courses from non-Computing faculties.
A9: K8 | B9: Year label: slip says 'YEAR 2', audit says 'BIL SEMESTER 5'. No effect on credits.

Sheet Sources & legend
A1: Key | B1: File (relative to Library) / meaning
A2: AUD | B2: Academic-Records\Graduation-Audit.pdf (scanned, read visually; printed 04 Oct 2026)
A3: RES | B3: Academic-Records\2025-2026\Semester-2\2025-2026-Sem-2-Exam-Results.pdf (KD 57, KK 61, JMN 155.66, CGPA 2.55)
A4: SLIP | B4: Academic-Records\2026-2027\Semester-1\2026-2027-Sem-1-Course-Registration.pdf (04 Oct 2026, 12 credits)
A5: CCS | B5: Academic-Records\Course-Completion-Status.pdf
A6: STR | B6: Academic-Program\SCSEH-Course-Structure-Intake-2024-2025-Rev-2024-11-05.pdf
A7: CUR | B7: Academic-Program\SCSEH-Curriculum-Course-List.pdf
A8: CAL | B8: Academic-Calendar-and-Timetables\Academic-Calendar-2026-2027-Corrected-2026-05-14.pdf
A9: FL | B9: Academic-Calendar-and-Timetables\Foreign-Languages-Timetable-2026-2027-Sem-1.pdf
A10: OLD | B10: Academic-Program\Mohammed-SCSEH-Study-Plan-2026-10-12.pdf (old AI-made plan, not official)
A11: MOH | B11: Mohammed's own statements/corrections (planned adds, colour meaning) - not a document
A12: OMAR | B12: The_Boots\01_Omar\STATE\CURRENT.md + OUTPUT\Mohammed_SCSEH_Plan_review_2026-10-13.md (status letter info: expected graduation 29 Aug 2029)
... A16: Cats | B16: T faculty core 82; E programme electives 18; U university 20 (8 general + 4 free electives x 3); B English/languages 6; K co-curriculum 2 = 128
